<mujoco>
 <visual>
<headlight ambient="0.5 0.5 0.5"/>
 </visual>
	<option timestep="0.001" integrator="RK4" gravity="0 0 -9.81">
		<flag sensornoise="disable" contact="enable" energy="enable"/>
	</option>
<asset>
	<texture builtin="gradient" height="100" rgb1="1 1 1" rgb2="0 0 0" type="skybox" width="100"/>
	<texture builtin="flat" height="1278" mark="cross" markrgb="1 1 1" name="texgeom" random="0.01" rgb1="0.8 0.6 0.4" rgb2="0.8 0.6 0.4" type="cube" width="127"/>
	<texture builtin="checker" height="100" name="texplane" rgb1="0 0 0" rgb2="0.8 0.8 0.8" type="2d" width="100"/>
	<material name="MatPlane" reflectance="0.1" shininess="0" specular="1" texrepeat="10 10" texture="texplane"/>
	<material name="geom" texture="texgeom" texuniform="true"/>
</asset>

<worldbody>
    <light cutoff="100" diffuse="1 1 1" dir="-0 0 -1.3" directional="true" exponent="1" pos="0 0 1.3" specular=".1 .1 .1"/>
    <geom conaffinity="1" condim="3" material="MatPlane" name="floor" pos="0 0 0" rgba="0.8 0.9 0.8 1" size="40 40 40" type="plane"/>
	<camera name="camera" mode="trackcom"  pos="2.0 -7. 4.5" euler="60 -0 0" />
	
		<!-- <geom type="plane" size="100 1 0.1" rgba=".9 0 0 1"/> -->
			<body name="platform_1" pos="0 0 0.5" euler = "0 0 0">
				<geom type="box" size="0.2 0.2 0.5" rgba = "0.39 0.26 0.12 1"/>				
			</body>
			<body name="platform_2" pos="1 0 0.5" euler = "0 0 0">
				<geom type="box" size="0.2 0.2 0.5" rgba = "0.39 0.26 0.12 1"/>				
			</body>
			<body name="platform_3" pos="2 0 0.5" euler = "0 0 0">
				<geom type="box" size="0.2 0.2 0.5" rgba = "0.39 0.26 0.12 1"/>				
			</body>
			<body name="platform_4" pos="3 0 0.5" euler = "0 0 0">
				<geom type="box" size="0.2 0.2 0.5" rgba = "0.39 0.26 0.12 1"/>				
			</body>
			<body name="platform_5" pos="4 0 0.5" euler = "0 0 0">
				<geom type="box" size="0.2 0.2 0.5" rgba = "0.39 0.26 0.12 1"/>				
			</body>
			<body name="platform_6" pos="5 0 0.5" euler = "0 0 0">
				<geom type="box" size="0.2 0.2 0.5" rgba = "0.39 0.26 0.12 1"/>				
			</body>
			<body name="torso" pos="0 0 2">
				<site name="range_site_1" pos="0 0 0.1" size="0.1 0.1 0.1" euler="0 110 0" type="cylinder"/>
				<site name="range_site_2" pos="0 0 0.1" size="0.1 0.1 0.1" euler="0 115 0" type="cylinder"/>
				<site name="range_site_3" pos="0 0 0.1" size="0.1 0.1 0.1" euler="0 120 0" type="cylinder"/>
				<site name="range_site_4" pos="0 0 0.1" size="0.1 0.1 0.1" euler="0 125 0" type="cylinder"/>
				<site name="range_site_5" pos="0 0 0.1" size="0.1 0.1 0.1" euler="0 130 0" type="cylinder"/>
				<site name="range_site_6" pos="0 0 0.1" size="0.1 0.1 0.1" euler="0 135 0" type="cylinder"/>
				<site name="range_site_7" pos="0 0 0.1" size="0.1 0.1 0.1" euler="0 140 0" type="cylinder"/>
				<site name="range_site_8" pos="0 0 0.1" size="0.1 0.1 0.1" euler="0 145 0" type="cylinder"/>
				<site name="range_site_9" pos="0 0 0.1" size="0.1 0.1 0.1" euler="0 150 0" type="cylinder"/>
				<site name="range_site_10" pos="0 0 0.1" size="0.1 0.1 0.1" euler="0 155 0" type="cylinder"/>
				<site name="accel_site" pos="0 0 0" size="0.1 0.1 0.1" euler="0 0 0" type="cylinder"/>
				<site name="gyro_site" pos="0 0 0" size="0.1 0.1 0.1" euler="0 0 0" type="cylinder"/>
				<joint name="x" type="slide" pos="0 0 0" axis="1 0 0" />
				<joint name="z" type="slide" pos="0 0 0" axis="0 0 1" />
				<geom type="sphere" size="0.1" rgba=".9 .9 .9 1" mass="1"/>
				<body name="leg" pos="0 0 -0.5" euler="0 0 0">
					<joint name="hip" type="hinge" pos="0 0 0.5" axis="0 -1 0" />
					<geom type="cylinder" size=".05 .5" rgba="0 .9 0 1" mass="1"/>
					<body name="foot" pos="0 0 -0.75">
					<joint name="knee" type="slide" pos="0 0 0.25" axis="0 0 -1" />
					<geom type="cylinder" pos="0 0 0.125" size=".01 .125" rgba="0 0 .9 1" mass="0"/>
					<geom type="sphere" size="0.05" rgba=".9 .9 0 1" mass="0.1"/>
					</body>
				</body>
			</body>
	</worldbody>

	<sensor>
		<rangefinder name="range_sensor_1" site="range_site_1" cutoff="10" />
		<rangefinder name="range_sensor_2" site="range_site_2" cutoff="10" />
		<rangefinder name="range_sensor_3" site="range_site_3" cutoff="10" />
		<rangefinder name="range_sensor_4" site="range_site_4" cutoff="10" />
		<rangefinder name="range_sensor_5" site="range_site_5" cutoff="10" />
		<rangefinder name="range_sensor_6" site="range_site_6" cutoff="10" />
		<rangefinder name="range_sensor_7" site="range_site_7" cutoff="10" />
		<rangefinder name="range_sensor_8" site="range_site_8" cutoff="10" />
		<rangefinder name="range_sensor_9" site="range_site_9" cutoff="10" />
		<rangefinder name="range_sensor_10" site="range_site_10" cutoff="10" />
		<accelerometer name="accel_sensor" site="accel_site" />
		<gyro name="gyro_sensor" site="gyro_site" />
	</sensor>

</mujoco>
